Workbook

Sheet CorST
A1: Слово | B1: Частота-CorST | C1: IPM-CorST | D1: Ранг-CorST | E1: Номер строки, на которой слово стоит в RLC | F1: IPM-RLC
A2: в | B2: 35889 | C2: 11520.564 | D2: =RANK(B2,B:B) -> 1 | E2: =MATCH(A2,RLC!A:A,0) -> 8126 | F2: {=INDEX(RLC!C:C,E2)} -> 37993.234 | G2: {=INDEX(RLC!D:D,F2)}
A3: и | B3: 31435 | C3: 10090.806 | D3: =RANK(B3,B:B) -> 2 | E3: =MATCH(A3,RLC!A:A,0) -> 8125 | F3: {=INDEX(RLC!C:C,E3)} -> 38334.702
A4: на | B4: 13212 | C4: 4241.1239 | D4: =RANK(B4,B:B) -> 3 | E4: =MATCH(A4,RLC!A:A,0) -> 8124 | F4: {=INDEX(RLC!C:C,E4)} -> 13265.412
A5: не | B5: 11811 | C5: 3791.3953 | D5: =RANK(B5,B:B) -> 4 | E5: =MATCH(A5,RLC!A:A,0) -> 8123 | F5: {=INDEX(RLC!C:C,E5)} -> 12860.168
A6: с | B6: 11363 | C6: 3647.5848 | D6: =RANK(B6,B:B) -> 5 | E6: =MATCH(A6,RLC!A:A,0) -> 8122 | F6: {=INDEX(RLC!C:C,E6)} -> 9178.432
A7: что | B7: 10265 | C7: 3295.1208 | D7: =RANK(B7,B:B) -> 6 | E7: =MATCH(A7,RLC!A:A,0) -> 8121 | F7: {=INDEX(RLC!C:C,E7)} -> 16305.402
A8: как | B8: 7396 | C8: 2374.1562 | D8: =RANK(B8,B:B) -> 7 | E8: =MATCH(A8,RLC!A:A,0) -> 8120 | F8: {=INDEX(RLC!C:C,E8)} -> 8273.6097
A9: к | B9: 6790 | C9: 2179.6269 | D9: =RANK(B9,B:B) -> 8 | E9: =MATCH(A9,RLC!A:A,0) -> 8119 | F9: {=INDEX(RLC!C:C,E9)} -> 4742.0127
A10: а | B10: 5924 | C10: 1901.6362 | D10: =RANK(B10,B:B) -> 9 | E10: =MATCH(A10,RLC!A:A,0) -> 8118 | F10: {=INDEX(RLC!C:C,E10)} -> 3449.2197
A11: для | B11: 5652 | C11: 1814.3227 | D11: =RANK(B11,B:B) -> 10 | E11: =MATCH(A11,RLC!A:A,0) -> 8117 | F11: {=INDEX(RLC!C:C,E11)} -> 5009.0748
A12: по | B12: 5634 | C12: 1808.5447 | D12: =RANK(B12,B:B) -> 11 | E12: =MATCH(A12,RLC!A:A,0) -> 8116 | F12: {=INDEX(RLC!C:C,E12)} -> 4641.034
A13: о | B13: 4912 | C13: 1576.7787 | D13: =RANK(B13,B:B) -> 12 | E13: =MATCH(A13,RLC!A:A,0) -> 8115 | F13: {=INDEX(RLC!C:C,E13)} -> 5022.3615
A14: из | B14: 4365 | C14: 1401.1887 | D14: =RANK(B14,B:B) -> 13 | E14: =MATCH(A14,RLC!A:A,0) -> 8114 | F14: {=INDEX(RLC!C:C,E14)} -> 4432.4333
... A1349: форм | B1349: 92 | C1349: 29.532501 | D1349: =RANK(B1349,B:B) -> 1326 | E1349: =MATCH(A1349,RLC!A:A,0) -> 6925 | F1349: {=INDEX(RLC!C:C,E1349)} -> 21.258673
A1350: школе | B1350: 92 | C1350: 29.532501 | D1350: =RANK(B1350,B:B) -> 1326 | E1350: =MATCH(A1350,RLC!A:A,0) -> 6924 | F1350: {=INDEX(RLC!C:C,E1350)} -> 259.09008 | G1350: =C1350>E1350 -> FALSE
A1351: элементов | B1351: 92 | C1351: 29.532501 | D1351: =RANK(B1351,B:B) -> 1326 | E1351: =MATCH(A1351,RLC!A:A,0) -> 6923 | F1351: {=INDEX(RLC!C:C,E1351)} -> 27.902008
A1352: этими | B1352: 92 | C1352: 29.532501 | D1352: =RANK(B1352,B:B) -> 1326 | E1352: =MATCH(A1352,RLC!A:A,0) -> 6922 | F1352: {=INDEX(RLC!C:C,E1352)} -> 77.062689
A1353: артикля | B1353: 91 | C1353: 29.211495 | D1353: =RANK(B1353,B:B) -> 1352 | E1353: =MATCH(A1353,RLC!A:A,0) -> #N/A | F1353: {=INDEX(RLC!C:C,E1353)} -> #N/A
A1354: всему | B1354: 91 | C1354: 29.211495 | D1354: =RANK(B1354,B:B) -> 1352 | E1354: =MATCH(A1354,RLC!A:A,0) -> 6921 | F1354: {=INDEX(RLC!C:C,E1354)} -> 144.82471
A1355: выполнения | B1355: 91 | C1355: 29.211495 | D1355: =RANK(B1355,B:B) -> 1352 | E1355: =MATCH(A1355,RLC!A:A,0) -> #N/A | F1355: {=INDEX(RLC!C:C,E1355)} -> #N/A
A1356: достоевский | B1356: 91 | C1356: 29.211495 | D1356: =RANK(B1356,B:B) -> 1352 | E1356: =MATCH(A1356,RLC!A:A,0) -> #N/A | F1356: {=INDEX(RLC!C:C,E1356)} -> #N/A
A1357: менеджмента | B1357: 91 | C1357: 29.211495 | D1357: =RANK(B1357,B:B) -> 1352 | E1357: =MATCH(A1357,RLC!A:A,0) -> 6920 | F1357: {=INDEX(RLC!C:C,E1357)} -> 39.860012
A1358: наша | B1358: 91 | C1358: 29.211495 | D1358: =RANK(B1358,B:B) -> 1352 | E1358: =MATCH(A1358,RLC!A:A,0) -> 6919 | F1358: {=INDEX(RLC!C:C,E1358)} -> 193.98539
A1359: поднятая | B1359: 91 | C1359: 29.211495 | D1359: =RANK(B1359,B:B) -> 1352 | E1359: =MATCH(A1359,RLC!A:A,0) -> #N/A | F1359: {=INDEX(RLC!C:C,E1359)} -> #N/A
A1360: постепенно | B1360: 91 | C1360: 29.211495 | D1360: =RANK(B1360,B:B) -> 1352 | E1360: =MATCH(A1360,RLC!A:A,0) -> 6918 | F1360: {=INDEX(RLC!C:C,E1360)} -> 46.503347
A1361: рублей | B1361: 91 | C1361: 29.211495 | D1361: =RANK(B1361,B:B) -> 1352 | E1361: =MATCH(A1361,RLC!A:A,0) -> 6917 | F1361: {=INDEX(RLC!C:C,E1361)} -> 67.76202
A1362: сегодняшний | B1362: 91 | C1362: 29.211495 | D1362: =RANK(B1362,B:B) -> 1352 | E1362: =MATCH(A1362,RLC!A:A,0) -> 6916 | F1362: {=INDEX(RLC!C:C,E1362)} -> 62.447352
... A1716: чехов | B1716: 73 | C1716: 23.433397 | D1716: =RANK(B1716,B:B) -> 1684 | E1716: =MATCH(A1716,RLC!A:A,0) -> #N/A | F1716: {=INDEX(RLC!C:C,E1716)} -> #N/A
A1717: шапочка | B1717: 73 | C1717: 23.433397 | D1717: =RANK(B1717,B:B) -> 1684 | E1717: =MATCH(A1717,RLC!A:A,0) -> 6655 | F1717: {=INDEX(RLC!C:C,E1717)} -> 34.545343 | G1717: =C1717>E1717 -> FALSE
A1718: широко | B1718: 73 | C1718: 23.433397 | D1718: =RANK(B1718,B:B) -> 1684 | E1718: =MATCH(A1718,RLC!A:A,0) -> 6654 | F1718: {=INDEX(RLC!C:C,E1718)} -> 73.076688 | G1718: =C1718>E1718 -> FALSE
A1719: эмоций | B1719: 73 | C1719: 23.433397 | D1719: =RANK(B1719,B:B) -> 1684 | E1719: =MATCH(A1719,RLC!A:A,0) -> 6653 | F1719: {=INDEX(RLC!C:C,E1719)} -> 15.944005
A1720: большие | B1720: 72 | C1720: 23.112392 | D1720: =RANK(B1720,B:B) -> 1719 | E1720: =MATCH(A1720,RLC!A:A,0) -> 6652 | F1720: {=INDEX(RLC!C:C,E1720)} -> 128.8807
A1721: большого | B1721: 72 | C1721: 23.112392 | D1721: =RANK(B1721,B:B) -> 1719 | E1721: =MATCH(A1721,RLC!A:A,0) -> 6651 | F1721: {=INDEX(RLC!C:C,E1721)} -> 42.517346
A1722: ведет | B1722: 72 | C1722: 23.112392 | D1722: =RANK(B1722,B:B) -> 1719 | E1722: =MATCH(A1722,RLC!A:A,0) -> 6650 | F1722: {=INDEX(RLC!C:C,E1722)} -> 31.888009
A1723: вниз | B1723: 72 | C1723: 23.112392 | D1723: =RANK(B1723,B:B) -> 1719 | E1723: =MATCH(A1723,RLC!A:A,0) -> 6649 | F1723: {=INDEX(RLC!C:C,E1723)} -> 39.860012
A1724: вузов | B1724: 72 | C1724: 23.112392 | D1724: =RANK(B1724,B:B) -> 1719 | E1724: =MATCH(A1724,RLC!A:A,0) -> 6648 | F1724: {=INDEX(RLC!C:C,E1724)} -> 17.272672
A1725: выражений | B1725: 72 | C1725: 23.112392 | D1725: =RANK(B1725,B:B) -> 1719 | E1725: =MATCH(A1725,RLC!A:A,0) -> 6647 | F1725: {=INDEX(RLC!C:C,E1725)} -> 29.230675
A1726: гражданским | B1726: 72 | C1726: 23.112392 | D1726: =RANK(B1726,B:B) -> 1719 | E1726: =MATCH(A1726,RLC!A:A,0) -> #N/A | F1726: {=INDEX(RLC!C:C,E1726)} -> #N/A
A1727: изучить | B1727: 72 | C1727: 23.112392 | D1727: =RANK(B1727,B:B) -> 1719 | E1727: =MATCH(A1727,RLC!A:A,0) -> 6646 | F1727: {=INDEX(RLC!C:C,E1727)} -> 25.244674
...

Sheet RLC
A1: Слово | B1: Частота-RLC | C1: IPM-RLC | D1: Ранг-RLC | E1: Номер строки, на которой слово стоит в CorST
A2: напишите | B2: 182 | C2: 241.8174 | D2: =RANK(B2,B:B) -> 425 | E2: =MATCH(A2,CorST!A:A,0) -> 10995
A3: озеро | B3: 173 | C3: 229.8594 | D3: =RANK(B3,B:B) -> 452 | E3: =MATCH(A3,CorST!A:A,0) -> 10996
A4: антибиотиков | B4: 156 | C4: 207.27206 | D4: =RANK(B4,B:B) -> 501 | E4: =MATCH(A4,CorST!A:A,0) -> 10997
A5: американцев | B5: 153 | C5: 203.28606 | D5: =RANK(B5,B:B) -> 517 | E5: =MATCH(A5,CorST!A:A,0) -> 10998
A6: байкал | B6: 150 | C6: 199.30006 | D6: =RANK(B6,B:B) -> 530 | E6: =MATCH(A6,CorST!A:A,0) -> 10999
A7: войне | B7: 146 | C7: 193.98539 | D7: =RANK(B7,B:B) -> 549 | E7: =MATCH(A7,CorST!A:A,0) -> 11000
A8: геополитика | B8: 134 | C8: 178.04139 | D8: =RANK(B8,B:B) -> 601 | E8: =MATCH(A8,CorST!A:A,0) -> 11001
A9: американцы | B9: 132 | C9: 175.38405 | D9: =RANK(B9,B:B) -> 606 | E9: =MATCH(A9,CorST!A:A,0) -> 11002
A10: маяковского | B10: 131 | C10: 174.05538 | D10: =RANK(B10,B:B) -> 610 | E10: =MATCH(A10,CorST!A:A,0) -> 11003
A11: советском | B11: 130 | C11: 172.72672 | D11: =RANK(B11,B:B) -> 619 | E11: =MATCH(A11,CorST!A:A,0) -> 11004
A12: озера | B12: 127 | C12: 168.74072 | D12: =RANK(B12,B:B) -> 628 | E12: =MATCH(A12,CorST!A:A,0) -> 11005
A13: пенициллина | B13: 127 | C13: 168.74072 | D13: =RANK(B13,B:B) -> 628 | E13: =MATCH(A13,CorST!A:A,0) -> 11006
... A8127: слово | B8127: 407 | C8127: 540.76749 | D8127: =RANK(B8127,B:B) -> 174 | E8127: =MATCH(A8127,CorST!A:A,0) -> 1

Sheet merge
A1: Слово | B1: IPM-CorST | C1: IPM-CorST
A2: в | B2: 11520.564 | C2: 37993.234
A3: и | B3: 10090.806 | C3: 38334.702
A4: на | B4: 4241.1239 | C4: 13265.412
A5: не | B5: 3791.3953 | C5: 12860.168
A6: с | B6: 3647.5848 | C6: 9178.432
A7: что | B7: 3295.1208 | C7: 16305.402
A8: как | B8: 2374.1562 | C8: 8273.6097
A9: к | B9: 2179.6269 | C9: 4742.0127
A10: а | B10: 1901.6362 | C10: 3449.2197
A11: для | B11: 1814.3227 | C11: 5009.0748
A12: по | B12: 1808.5447 | C12: 4641.034
A13: о | B13: 1576.7787 | C13: 5022.3615
... A61: работы | B61: 349.57492 | C61: 482.30614
A62: предлога | B62: 347.9699
A63: ее | B63: 345.40185 | C63: 987.19962
A64: исследования | B64: 343.47582 | C64: 180.69872
A65: м | B65: 343.47582 | C65: 196.64272
A66: человека | B66: 340.90778 | C66: 1162.5837
A67: языка | B67: 340.90778 | C67: 749.36822
A68: например | B68: 337.05571 | C68: 1194.4717
A69: образом | B69: 334.80867 | C69: 528.80949
A70: чем | B70: 332.56164 | C70: 1353.9117
A71: когда | B71: 332.24063 | C71: 3013.4169
A72: тем | B72: 323.89449 | C72: 976.57029
A73: уже | B73: 321.96846 | C73: 1037.689
A74: этот | B74: 321.64745 | C74: 1195.8003
... A114: люди | B114: 218.6047 | C114: 1909.2946
A115: предлогов | B115: 215.07365
A116: статьи | B116: 213.14761 | C116: 310.90809
A117: п | B117: 211.86359 | C117: 132.86671
A118: после | B118: 211.54259 | C118: 1567.8271
A119: над | B119: 209.29555 | C119: 389.29945
A120: больше | B120: 208.97454 | C120: 1307.4084
A121: несколько | B121: 207.36951 | C121: 572.6555
A122: данной | B122: 204.48047 | C122: 70.419354
A123: была | B123: 203.19644 | C123: 1792.3719
A124: этих | B124: 203.19644 | C124: 615.17285
A125: потому | B125: 202.55443 | C125: 2012.9306
A126: имеет | B126: 202.23343 | C126: 659.01886
...

Sheet Sheet5
A1: напишите | B1: 182 | C1: 241.8174 | D1: =RANK(B1,B:B) -> 1 | E1: =MATCH(A1,CorST!A:A,0) -> 10995
A2: озеро | B2: 173 | C2: 229.8594 | D2: =RANK(B2,B:B) -> 2 | E2: =MATCH(A2,CorST!A:A,0) -> 10996
A3: антибиотиков | B3: 156 | C3: 207.27206 | D3: =RANK(B3,B:B) -> 3 | E3: =MATCH(A3,CorST!A:A,0) -> 10997
A4: американцев | B4: 153 | C4: 203.28606 | D4: =RANK(B4,B:B) -> 4 | E4: =MATCH(A4,CorST!A:A,0) -> 10998
A5: байкал | B5: 150 | C5: 199.30006 | D5: =RANK(B5,B:B) -> 5 | E5: =MATCH(A5,CorST!A:A,0) -> 10999
A6: войне | B6: 146 | C6: 193.98539 | D6: =RANK(B6,B:B) -> 6 | E6: =MATCH(A6,CorST!A:A,0) -> 11000
A7: геополитика | B7: 134 | C7: 178.04139 | D7: =RANK(B7,B:B) -> 7 | E7: =MATCH(A7,CorST!A:A,0) -> 11001
A8: американцы | B8: 132 | C8: 175.38405 | D8: =RANK(B8,B:B) -> 8 | E8: =MATCH(A8,CorST!A:A,0) -> 11002
A9: маяковского | B9: 131 | C9: 174.05538 | D9: =RANK(B9,B:B) -> 9 | E9: =MATCH(A9,CorST!A:A,0) -> 11003
A10: советском | B10: 130 | C10: 172.72672 | D10: =RANK(B10,B:B) -> 10 | E10: =MATCH(A10,CorST!A:A,0) -> 11004
A11: озера | B11: 127 | C11: 168.74072 | D11: =RANK(B11,B:B) -> 11 | E11: =MATCH(A11,CorST!A:A,0) -> 11005
A12: пенициллина | B12: 127 | C12: 168.74072 | D12: =RANK(B12,B:B) -> 11 | E12: =MATCH(A12,CorST!A:A,0) -> 11006
... A3073: японский | B3073: 10 | C3073: 13.286671 | D3073: =RANK(B3073,B:B) -> 2635 | E3073: =MATCH(A3073,CorST!A:A,0) -> #N/A
